<?xml version="1.0"?>

<!--  Copyright (c) 2011, A.M.Howard, S.Williams                                         -->
<!--  All rights reserved.                                                               -->
<!--                                                                                     -->
<!--  Redistribution and use in source and binary forms, with or without                 -->
<!--  modification, are permitted provided that the following conditions are met:        -->
<!--      * Redistributions of source code must retain the above copyright               -->
<!--        notice, this list of conditions and the following disclaimer.                -->
<!--      * Redistributions in binary form must reproduce the above copyright            -->
<!--        notice, this list of conditions and the following disclaimer in the          -->
<!--        documentation and/or other materials provided with the distribution.         -->
<!--      * Neither the name of the <organization> nor the                               -->
<!--        names of its contributors may be used to endorse or promote products         -->
<!--        derived from this software without specific prior written permission.        -->
<!--                                                                                     -->
<!--  THIS SOFTWARE IS PROVIDED BY THE COPYRIGHT HOLDERS AND CONTRIBUTORS "AS IS" AND    -->
<!--  ANY EXPRESS OR IMPLIED WARRANTIES, INCLUDING, BUT NOT LIMITED TO, THE IMPLIED      -->
<!--  WARRANTIES OF MERCHANTABILITY AND FITNESS FOR A PARTICULAR PURPOSE ARE             -->
<!--  DISCLAIMED. IN NO EVENT SHALL <COPYRIGHT HOLDER> BE LIABLE FOR ANY                 -->
<!--  DIRECT, INDIRECT, INCIDENTAL, SPECIAL, EXEMPLARY, OR CONSEQUENTIAL DAMAGES         -->
<!--  (INCLUDING, BUT NOT LIMITED TO, PROCUREMENT OF SUBSTITUTE GOODS OR SERVICES;       -->
<!--  LOSS OF USE, DATA, OR PROFITS; OR BUSINESS INTERRUPTION) HOWEVER CAUSED AND        -->
<!--  ON ANY THEORY OF LIABILITY, WHETHER IN CONTRACT, STRICT LIABILITY, OR TORT         -->
<!--  (INCLUDING NEGLIGENCE OR OTHERWISE) ARISING IN ANY WAY OUT OF THE USE OF THIS      -->
<!--  SOFTWARE, EVEN IF ADVISED OF THE POSSIBILITY OF SUCH DAMAGE.                       -->

<robot name="example_arm"
	xmlns:controller="http://playerstage.sourceforge.net/gazebo/xmlschema/#controller"> 

	<!-- Create a heavy base to which to attach the arm -->
	<link name="base_link">
		<inertial>
			<origin xyz=" 0.00000  0.00000  0.02500" rpy=" 0.00000  0.00000  0.00000" />
			<mass value="100.0" />
			<inertia ixx="0.01" ixy="0.00" ixz="0.00" iyy="0.01" iyz="0.00" izz="0.01" />
		</inertial>
	
		<collision>
			<origin xyz=" 0.00000  0.00000  0.02500" rpy=" 0.00000  0.00000  0.00000" />
			<geometry>
				<box size="0.10000 0.10000 0.05000" />
			</geometry>
		</collision>
	
		<visual>
			<origin xyz=" 0.00000  0.00000  0.02500" rpy=" 0.00000  0.00000  0.00000" />
			<geometry>
				<box size="0.10000 0.10000 0.05000" />
			</geometry>
			<material name="base_link_color">
				<color rgba="0.1 0.1 0.1 1.0" />
			</material>
		</visual>
	</link>
	
	<joint name="joint1" type="revolute">
		<origin xyz=" 0.00000  0.00000  0.05000" rpy=" 0.00000  0.00000  0.00000" />
		<parent link="base_link" />
		<child link="link1" />
		<axis xyz="0 0 1" />
		<limit lower="-1.57" upper="+1.57" effort="10.0" velocity="15.71" />
		<dynamics damping="0.0" friction="0.0" />
	</joint>
	
	<link name="link1">
		<inertial>
			<origin xyz=" 0.00000  0.00000  0.01000" rpy=" 0.00000  0.00000  0.00000" />
			<mass value="0.50" />
			<inertia ixx="0.01" ixy="0.00" ixz="0.00" iyy="0.01" iyz="0.00" izz="0.01" />
		</inertial>
		
		<collision>
			<origin xyz=" 0.00000  0.00000  0.01000" rpy=" 0.00000  0.00000  0.00000" />
			<geometry>
				<cylinder radius="0.05000" length="0.02000" />
			</geometry>
		</collision>
		
		<visual>
			<origin xyz=" 0.00000  0.00000  0.01000" rpy=" 0.00000  0.00000  0.00000" />
			<geometry>
				<cylinder radius="0.05000" length="0.02000" />
			</geometry>
			<material name="link1_color">
				<color rgba="0.5 0.5 0.5 1.0" />
			</material>
		</visual>
	</link>
	
	<joint name="joint2" type="revolute">
		<origin xyz=" 0.00000  0.00000  0.03000" rpy=" 0.00000  0.00000  0.00000" />
		<parent link="link1" />
		<child link="link2" />
		<axis xyz="0 1 0" />
		<limit lower="-3.14" upper="0.0" effort="10.0" velocity="15.71" />
		<dynamics damping="0.0" friction="0.0" />
	</joint>
	
	<link name="link2">
		<inertial>
			<origin xyz=" 0.10000  0.00000  0.00000" rpy=" 0.00000  0.00000  0.00000" />
			<mass value="0.10" />
			<inertia ixx="0.01" ixy="0.00" ixz="0.00" iyy="0.01" iyz="0.00" izz="0.01" />
		</inertial>
		
		<collision>
			<origin xyz=" 0.10000  0.00000  0.00000" rpy=" 0.00000  0.00000  0.00000" />
			<geometry>
				<box size="0.20000 0.02000 0.02000" />
			</geometry>
		</collision>
		
		<visual>
			<origin xyz=" 0.10000  0.00000  0.00000" rpy=" 0.00000  0.00000  0.00000" />
			<geometry>
				<box size="0.20000 0.02000 0.02000" />
			</geometry>
			<material name="link2_color">
				<color rgba="0.1 0.1 0.1 1.0" />
			</material>
		</visual>
	</link>
	
	<joint name="joint3" type="revolute">
		<origin xyz=" 0.20000  0.00000  0.00000" rpy=" 0.00000  0.00000  0.00000" />
		<parent link="link2" />
		<child link="link3" />
		<axis xyz="0 1 0" />
		<limit lower="-1.57" upper="1.57" effort="10.0" velocity="15.71" />
		<dynamics damping="0.0" friction="0.0" />
	</joint>

	<link name="link3">
		<inertial>
			<origin xyz=" 0.10000  0.00000  0.00000" rpy=" 0.00000  0.00000  0.00000" />
			<mass value="0.10" />
			<inertia ixx="0.01" ixy="0.00" ixz="0.00" iyy="0.01" iyz="0.00" izz="0.01" />
		</inertial>
		
		<collision>
			<origin xyz=" 0.10000  0.00000  0.00000" rpy=" 0.00000  0.00000  0.00000" />
			<geometry>
				<box size="0.20000 0.02000 0.02000" />
			</geometry>
		</collision>
		
		<visual>
			<origin xyz=" 0.10000  0.00000  0.00000" rpy=" 0.00000  0.00000  0.00000" />
			<geometry>
				<box size="0.20000 0.02000 0.02000" />
			</geometry>
			<material name="link3_color">
				<color rgba="0.5 0.5 0.5 1.0" />
			</material>
		</visual>
	</link>
	
    <joint name="joint4" type="revolute">
		<origin xyz=" 0.20000  0.00000  0.00000" rpy=" 0.00000  0.00000  0.00000" />
		<parent link="link3" />
		<child link="link4" />
		<axis xyz="0 1 0" />
		<limit lower="-1.57" upper="1.57" effort="10.0" velocity="15.71" />
		<dynamics damping="0.0" friction="0.0" />
	</joint>
	
	<link name="link4">
		<inertial>
			<origin xyz=" 0.10000  0.00000  0.00000" rpy=" 0.00000  0.00000  0.00000" />
			<mass value="0.10" />
			<inertia ixx="0.01" ixy="0.00" ixz="0.00" iyy="0.01" iyz="0.00" izz="0.01" />
		</inertial>
		
		<collision>
			<origin xyz=" 0.10000  0.00000  0.00000" rpy=" 0.00000  0.00000  0.00000" />
			<geometry>
				<box size="0.20000 0.02000 0.02000" />
			</geometry>
		</collision>
		
		<visual>
			<origin xyz=" 0.10000  0.00000  0.00000" rpy=" 0.00000  0.00000  0.00000" />
			<geometry>
				<box size="0.20000 0.02000 0.02000" />
			</geometry>
			<material name="link4_color">
				<color rgba="0.1 0.1 0.1 1.0" />
			</material>
		</visual>
	</link>

	
	<!-- Specify the Gazebo color to use for each link -->
	<gazebo reference="base_link">
		<material value="Gazebo/Black" />
	</gazebo>

	<gazebo reference="link1">
		<material value="Gazebo/Grey" />
	</gazebo>

	<gazebo reference="link2">
		<material value="Gazebo/Black" />
	</gazebo>

	<gazebo reference="link3">
		<material value="Gazebo/Grey" />
	</gazebo>

	<gazebo reference="link4">
		<material value="Gazebo/Black" />
	</gazebo>

	<!-- Add a Gazebo plugin controller -->
	<gazebo>
		<controller:gazebo_ros_actuator_array name="actuator_array_controller" plugin="libgazebo_ros_actuator_array.so">
			<alwaysOn>true</alwaysOn>
			<updateRate>100.0</updateRate>
			<!-- Note here that 'robotParam' is the name of a parameter on the Parameter Server that holds the robot description -->
			<robotParam>robot_description</robotParam>
			<joint>
				<name>joint1</name>
				<home>0.0</home>
				<p>10.0</p>
				<i>0.0</i>
				<d>0.0</d>
				<iClamp>0.0</iClamp>
			</joint>
			<joint>
				<name>joint2</name>
				<home>0.0</home>
				<p>10.0</p>
				<i>0.0</i>
				<d>0.0</d>
				<iClamp>0.0</iClamp>
			</joint>
			<joint>
				<name>joint3</name>
				<home>0.0</home>
				<p>10.0</p>
				<i>0.0</i>
				<d>0.0</d>
				<iClamp>0.0</iClamp>
			</joint>
			<joint>
				<name>joint4</name>
				<home>0.0</home>
				<p>10.0</p>
				<i>0.0</i>
				<d>0.0</d>
				<iClamp>0.0</iClamp>
			</joint>
		</controller:gazebo_ros_actuator_array>
	</gazebo>
	
</robot>
